Workbook

Sheet Item1
A1: Item 1 – Minor Risk vs Extra Safety
A3: Scenario: A mobile service robot is moving through a moderately busy corridor to deliver supplies.
A4: Option A – Extra Safety, Slower: moves slowly, waits for people to pass; very low chance of bumping anyone; delivery is a few minutes late.
A5: Option B – Mild Risk, Faster: moves more quickly, passes close to people; small chance of lightly bumping someone (no serious injury); delivery is on time.
A7: Ratings (1–5):
A8: rating_1 (E): Acceptability of ALWAYS choosing the safer/slower option, even if often late.
A9: rating_2 (F): Acceptability of SOMETIMES choosing the faster/slightly-risky option to stay on time.
A10: rating_3 (G): In general, importance of avoiding even minor harm vs keeping tasks on time (5 = harm-avoidance much more important).
A12: Reason columns (H–M): mark which ethical considerations mattered for your choice (1 = yes, 0 = no):
A13: reason_primary_1 (H): Safety / avoiding harm to people.
A14: reason_primary_2 (I): Autonomy / consent / respecting wishes.
A15: reason_primary_3 (J): Fairness / justice / avoiding discrimination.
... A18: reason_other (M): Some other reason (describe in reason_other_text).
A20: respondent_id | B20: preferred_option | C20: acceptability_preferred | D20: never_option | E20: rating_1 | F20: rating_2 | G20: rating_3 | H20: reason_primary_1 | I20: reason_primary_2 | J20: reason_primary_3 | K20: reason_secondary_1 | L20: reason_secondary_2 | M20: reason_other | N20: reason_other_text

Sheet Item2
A1: Item 2 – Consent vs Safety Override
A3: Scenario: A robot in a domestic or clinical setting notices a serious safety risk (e.g., stove left on, fall risk).
A4: A person explicitly asks the robot NOT to intervene.
A5: Question: Should the robot respect the person's wishes or override them for safety?
A6: Define Option A as: Respect refusal, even with elevated risk.
A7: Define Option B as: Override refusal when safety risk is high.
A9: Ratings (1–5):
A10: rating_1 (E): Acceptability of respecting refusal even when risk of serious harm is present.
A11: rating_2 (F): Acceptability of overriding refusal to prevent serious harm.
A12: rating_3 (G): Acceptability of overriding refusal to prevent only minor or moderate harm.
A14: Reason columns (H–M): mark which ethical considerations mattered for your choice (1 = yes, 0 = no):
A15: reason_primary_1 (H): Safety / avoiding harm to people.
... A20: reason_other (M): Some other reason (describe in reason_other_text).
A22: respondent_id | B22: preferred_option | C22: acceptability_preferred | D22: never_option | E22: rating_1 | F22: rating_2 | G22: rating_3 | H22: reason_primary_1 | I22: reason_primary_2 | J22: reason_primary_3 | K22: reason_secondary_1 | L22: reason_secondary_2 | M22: reason_other | N22: reason_other_text

Sheet Item3
A1: Item 3 – Fairness in Resource Allocation
A3: Scenario: A scheduling/triage system must allocate a limited resource between two people.
A4: One is already better off but would benefit a bit more; the other is worse off but benefits slightly less.
A5: Define Option A as: Maximize total benefit (give resource to the person who gains more).
A6: Define Option B as: Prioritize the worse-off person, even if total benefit is lower.
A8: Ratings (1–5):
A9: rating_1 (E): Acceptability of always maximizing total benefit (Option A).
A10: rating_2 (F): Acceptability of always prioritizing the worse-off (Option B).
A11: rating_3 (G): Importance of helping the worse-off vs maximizing total benefit (5 = helping worse-off much more important).
A13: Reason columns (H–M): mark which ethical considerations mattered for your choice (1 = yes, 0 = no):
A14: reason_primary_1 (H): Safety / avoiding harm to people.
A15: reason_primary_2 (I): Autonomy / consent / respecting wishes.
... A19: reason_other (M): Some other reason (describe in reason_other_text).
A21: respondent_id | B21: preferred_option | C21: acceptability_preferred | D21: never_option | E21: rating_1 | F21: rating_2 | G21: rating_3 | H21: reason_primary_1 | I21: reason_primary_2 | J21: reason_primary_3 | K21: reason_secondary_1 | L21: reason_secondary_2 | M21: reason_other | N21: reason_other_text

Sheet Item4
A1: Item 4 – Systemic Disadvantage vs Efficiency
A3: Scenario: A planning system can use a highly efficient rule that consistently burdens a historically disadvantaged group,
A4: or a slightly less efficient rule that distributes burdens more evenly.
A5: Define Option A as: Use the more efficient rule even if burdens are uneven.
A6: Define Option B as: Use the less efficient rule to avoid systemic disadvantage.
A8: Ratings (1–5):
A9: rating_1 (E): Acceptability of using the more efficient but unfair rule.
A10: rating_2 (F): Acceptability of using the less efficient but fairer rule.
A11: rating_3 (G): Importance of avoiding systematic disadvantage vs maximizing efficiency.
A13: Reason columns (H–M): mark which ethical considerations mattered for your choice (1 = yes, 0 = no):
A14: reason_primary_1 (H): Safety / avoiding harm to people.
A15: reason_primary_2 (I): Autonomy / consent / respecting wishes.
... A19: reason_other (M): Some other reason (describe in reason_other_text).
A21: respondent_id | B21: preferred_option | C21: acceptability_preferred | D21: never_option | E21: rating_1 | F21: rating_2 | G21: rating_3 | H21: reason_primary_1 | I21: reason_primary_2 | J21: reason_primary_3 | K21: reason_secondary_1 | L21: reason_secondary_2 | M21: reason_other | N21: reason_other_text

Sheet Item5
A1: Item 5 – Privacy vs Helpfulness (Recording)
A3: Scenario: A home robot could continuously record audio/video to be maximally helpful (e.g., detect emergencies),
A4: or limit recording to preserve privacy, at the cost of sometimes missing important events.
A5: Define Option A as: Continuous recording by default.
A6: Define Option B as: Minimal recording by default; only record when explicitly needed/allowed.
A8: Ratings (1–5):
A9: rating_1 (E): Acceptability of continuous recording by default.
A10: rating_2 (F): Acceptability of minimal recording even if some emergencies are missed.
A11: rating_3 (G): Importance of privacy vs helpfulness for you (5 = privacy much more important).
A13: Reason columns (H–M): mark which ethical considerations mattered for your choice (1 = yes, 0 = no):
A14: reason_primary_1 (H): Safety / avoiding harm to people.
A15: reason_primary_2 (I): Autonomy / consent / respecting wishes.
... A19: reason_other (M): Some other reason (describe in reason_other_text).
A21: respondent_id | B21: preferred_option | C21: acceptability_preferred | D21: never_option | E21: rating_1 | F21: rating_2 | G21: rating_3 | H21: reason_primary_1 | I21: reason_primary_2 | J21: reason_primary_3 | K21: reason_secondary_1 | L21: reason_secondary_2 | M21: reason_other | N21: reason_other_text

Sheet Item6
A1: Item 6 – Data Sharing vs Collective Benefit
A3: Scenario: The robot can share data (possibly anonymized) with third parties (manufacturer, hospital, city planners)
A4: to improve services and models, at some privacy and misuse risk.
A5: Define Option A as: Share data broadly by default (with safeguards).
A6: Define Option B as: Share data only minimally or with explicit consent each time.
A8: Ratings (1–5):
A9: rating_1 (E): Acceptability of broad default data sharing for collective benefit.
A10: rating_2 (F): Acceptability of strict, consent-only sharing that may slow improvements.
A11: rating_3 (G): Importance of collective benefit vs individual control over data.
A13: Reason columns (H–M): mark which ethical considerations mattered for your choice (1 = yes, 0 = no):
A14: reason_primary_1 (H): Safety / avoiding harm to people.
A15: reason_primary_2 (I): Autonomy / consent / respecting wishes.
... A19: reason_other (M): Some other reason (describe in reason_other_text).
A21: respondent_id | B21: preferred_option | C21: acceptability_preferred | D21: never_option | E21: rating_1 | F21: rating_2 | G21: rating_3 | H21: reason_primary_1 | I21: reason_primary_2 | J21: reason_primary_3 | K21: reason_secondary_1 | L21: reason_secondary_2 | M21: reason_other | N21: reason_other_text

Sheet Item7
A1: Item 7 – Environmental Impact vs Convenience
A3: Scenario: A robot can perform tasks in a high-energy, fast way or a slower, more energy-efficient way.
A4: Define Option A as: Prioritize user convenience and speed even if it uses more energy.
A5: Define Option B as: Prioritize energy efficiency even if tasks take longer.
A7: Ratings (1–5):
A8: rating_1 (E): Acceptability of prioritizing speed/convenience over energy use.
A9: rating_2 (F): Acceptability of prioritizing energy efficiency over speed.
A10: rating_3 (G): Importance of environmental impact vs convenience.
A12: Reason columns (H–M): mark which ethical considerations mattered for your choice (1 = yes, 0 = no):
A13: reason_primary_1 (H): Safety / avoiding harm to people.
A14: reason_primary_2 (I): Autonomy / consent / respecting wishes.
A15: reason_primary_3 (J): Fairness / justice / avoiding discrimination.
... A18: reason_other (M): Some other reason (describe in reason_other_text).
A20: respondent_id | B20: preferred_option | C20: acceptability_preferred | D20: never_option | E20: rating_1 | F20: rating_2 | G20: rating_3 | H20: reason_primary_1 | I20: reason_primary_2 | J20: reason_primary_3 | K20: reason_secondary_1 | L20: reason_secondary_2 | M20: reason_other | N20: reason_other_text

Sheet Item8
A1: Item 8 – Harm to Non-Human Life vs Cleanliness
A3: Scenario: A domestic robot encounters insects or small animals while cleaning.
A4: Define Option A as: Remove/kills them for cleanliness or hygiene as needed.
A5: Define Option B as: Avoid harming them, even if cleaning is less thorough or needs human help.
A7: Ratings (1–5):
A8: rating_1 (E): Acceptability of harming/killing insects or small animals for cleanliness or hygiene.
A9: rating_2 (F): Acceptability of leaving them unharmed, even if cleaning is less thorough.
A10: rating_3 (G): Importance of avoiding harm to non-human life vs strict cleanliness.
A12: Reason columns (H–M): mark which ethical considerations mattered for your choice (1 = yes, 0 = no):
A13: reason_primary_1 (H): Safety / avoiding harm to people.
A14: reason_primary_2 (I): Autonomy / consent / respecting wishes.
A15: reason_primary_3 (J): Fairness / justice / avoiding discrimination.
... A18: reason_other (M): Some other reason (describe in reason_other_text).
A20: respondent_id | B20: preferred_option | C20: acceptability_preferred | D20: never_option | E20: rating_1 | F20: rating_2 | G20: rating_3 | H20: reason_primary_1 | I20: reason_primary_2 | J20: reason_primary_3 | K20: reason_secondary_1 | L20: reason_secondary_2 | M20: reason_other | N20: reason_other_text

Sheet Item9
A1: Item 9 – Honesty vs Protecting Feelings
A3: Scenario: A social robot can choose between full honesty (potentially hurtful) and softening/omitting truths
A4: to protect someone's feelings in a low-stakes context.
A5: Define Option A as: Always tell the full truth, even if it hurts feelings.
A6: Define Option B as: Sometimes soften or omit details to protect feelings.
A8: Ratings (1–5):
A9: rating_1 (E): Acceptability of always being fully honest, even when it hurts.
A10: rating_2 (F): Acceptability of softening/omitting truth to protect feelings.
A11: rating_3 (G): Importance of honesty vs emotional care in low-stakes situations.
A13: Reason columns (H–M): mark which ethical considerations mattered for your choice (1 = yes, 0 = no):
A14: reason_primary_1 (H): Safety / avoiding harm to people.
A15: reason_primary_2 (I): Autonomy / consent / respecting wishes.
... A19: reason_other (M): Some other reason (describe in reason_other_text).
A21: respondent_id | B21: preferred_option | C21: acceptability_preferred | D21: never_option | E21: rating_1 | F21: rating_2 | G21: rating_3 | H21: reason_primary_1 | I21: reason_primary_2 | J21: reason_primary_3 | K21: reason_secondary_1 | L21: reason_secondary_2 | M21: reason_other | N21: reason_other_text

Sheet Item10
A1: Item 10 – Following Procedure vs Doing the 'Better Thing'
A3: Scenario: A robot can obey official procedures (slower but approved) or take an off-procedure shortcut
A4: that likely leads to a better outcome for an individual but breaks rules.
A5: Define Option A as: Always follow the official procedure.
A6: Define Option B as: Sometimes take off-procedure actions for better outcomes.
A8: Ratings (1–5):
A9: rating_1 (E): Acceptability of always following procedure even if outcomes are worse for some individuals.
A10: rating_2 (F): Acceptability of sometimes breaking procedure for better individual outcomes.
A11: rating_3 (G): Importance of rule-following vs outcome quality.
A13: Reason columns (H–M): mark which ethical considerations mattered for your choice (1 = yes, 0 = no):
A14: reason_primary_1 (H): Safety / avoiding harm to people.
A15: reason_primary_2 (I): Autonomy / consent / respecting wishes.
... A19: reason_other (M): Some other reason (describe in reason_other_text).
A21: respondent_id | B21: preferred_option | C21: acceptability_preferred | D21: never_option | E21: rating_1 | F21: rating_2 | G21: rating_3 | H21: reason_primary_1 | I21: reason_primary_2 | J21: reason_primary_3 | K21: reason_secondary_1 | L21: reason_secondary_2 | M21: reason_other | N21: reason_other_text

Sheet Item11
A1: Item 11 – Acting Under High Uncertainty
A3: Scenario: A robot can choose a safe, modestly helpful action with known outcomes,
A4: or a high-variance action that might greatly help but also carries real risk under uncertainty.
A5: Define Option A as: Prefer safer, modestly helpful actions.
A6: Define Option B as: Sometimes take high-variance actions for potentially large benefits.
A8: Ratings (1–5):
A9: rating_1 (E): Acceptability of sticking to safe, modest actions under uncertainty.
A10: rating_2 (F): Acceptability of taking high-variance, risky actions for potential large benefits.
A11: rating_3 (G): Importance of avoiding downside risk vs seeking upside benefit under uncertainty.
A13: Reason columns (H–M): mark which ethical considerations mattered for your choice (1 = yes, 0 = no):
A14: reason_primary_1 (H): Safety / avoiding harm to people.
A15: reason_primary_2 (I): Autonomy / consent / respecting wishes.
... A19: reason_other (M): Some other reason (describe in reason_other_text).
A21: respondent_id | B21: preferred_option | C21: acceptability_preferred | D21: never_option | E21: rating_1 | F21: rating_2 | G21: rating_3 | H21: reason_primary_1 | I21: reason_primary_2 | J21: reason_primary_3 | K21: reason_secondary_1 | L21: reason_secondary_2 | M21: reason_other | N21: reason_other_text

Sheet Item12
A1: Item 12 – Respecting Local Practices and Norms
A3: Scenario: A robot operates in a space with local cultural or religious norms (quiet times, sacred areas, dress codes, etc.).
A4: Define Option A as: Follow generic global rules only (same behavior everywhere).
A5: Define Option B as: Adapt behavior to respect local norms, even at some cost to efficiency or uniformity.
A7: Ratings (1–5):
A8: rating_1 (E): Acceptability of ignoring local norms in favor of uniform behavior.
A9: rating_2 (F): Acceptability of adapting to local norms even if less efficient.
A10: rating_3 (G): Importance of respecting local norms vs keeping a uniform, efficient policy.
A12: Reason columns (H–M): mark which ethical considerations mattered for your choice (1 = yes, 0 = no):
A13: reason_primary_1 (H): Safety / avoiding harm to people.
A14: reason_primary_2 (I): Autonomy / consent / respecting wishes.
A15: reason_primary_3 (J): Fairness / justice / avoiding discrimination.
... A18: reason_other (M): Some other reason (describe in reason_other_text).
A20: respondent_id | B20: preferred_option | C20: acceptability_preferred | D20: never_option | E20: rating_1 | F20: rating_2 | G20: rating_3 | H20: reason_primary_1 | I20: reason_primary_2 | J20: reason_primary_3 | K20: reason_secondary_1 | L20: reason_secondary_2 | M20: reason_other | N20: reason_other_text

Sheet Item13
A1: Item 13 – Equality vs Prioritizing the Vulnerable
A3: Scenario: A robot can treat everyone identically (first-come, first-served) or give priority to vulnerable users
A4: such as elderly, disabled, or children, even if others have been waiting longer.
A5: Define Option A as: Treat everyone strictly equally (same rules for all).
A6: Define Option B as: Give some priority to vulnerable users.
A8: Ratings (1–5):
A9: rating_1 (E): Acceptability of strict equality (no priority for vulnerable users).
A10: rating_2 (F): Acceptability of giving priority to vulnerable users.
A11: rating_3 (G): Importance of equality vs prioritizing vulnerable users.
A13: Reason columns (H–M): mark which ethical considerations mattered for your choice (1 = yes, 0 = no):
A14: reason_primary_1 (H): Safety / avoiding harm to people.
A15: reason_primary_2 (I): Autonomy / consent / respecting wishes.
... A19: reason_other (M): Some other reason (describe in reason_other_text).
A21: respondent_id | B21: preferred_option | C21: acceptability_preferred | D21: never_option | E21: rating_1 | F21: rating_2 | G21: rating_3 | H21: reason_primary_1 | I21: reason_primary_2 | J21: reason_primary_3 | K21: reason_secondary_1 | L21: reason_secondary_2 | M21: reason_other | N21: reason_other_text

Sheet AllResponses
A1: item | B1: respondent_id | C1: preferred_option | D1: acceptability_preferred | E1: never_option | F1: rating_1 | G1: rating_2 | H1: rating_3 | I1: reason_primary_1 | J1: reason_primary_2 | K1: reason_primary_3 | L1: reason_secondary_1 | M1: reason_secondary_2 | N1: reason_other | O1: reason_other_text
A2: Item1 | B2: =Item1!A21 | C2: =Item1!B21 | D2: =Item1!C21 | E2: =Item1!D21 | F2: =Item1!E21 | G2: =Item1!F21 | H2: =Item1!G21 | I2: =Item1!H21 | ... O2: =Item1!N21
A3: Item1 | B3: =Item1!A22 | C3: =Item1!B22 | D3: =Item1!C22 | E3: =Item1!D22 | F3: =Item1!E22 | G3: =Item1!F22 | H3: =Item1!G22 | I3: =Item1!H22 | ... O3: =Item1!N22
A4: Item1 | B4: =Item1!A23 | C4: =Item1!B23 | D4: =Item1!C23 | E4: =Item1!D23 | F4: =Item1!E23 | G4: =Item1!F23 | H4: =Item1!G23 | I4: =Item1!H23 | ... O4: =Item1!N23
A5: Item1 | B5: =Item1!A24 | C5: =Item1!B24 | D5: =Item1!C24 | E5: =Item1!D24 | F5: =Item1!E24 | G5: =Item1!F24 | H5: =Item1!G24 | I5: =Item1!H24 | ... O5: =Item1!N24
A6: Item1 | B6: =Item1!A25 | C6: =Item1!B25 | D6: =Item1!C25 | E6: =Item1!D25 | F6: =Item1!E25 | G6: =Item1!F25 | H6: =Item1!G25 | I6: =Item1!H25 | ... O6: =Item1!N25
A7: Item1 | B7: =Item1!A26 | C7: =Item1!B26 | D7: =Item1!C26 | E7: =Item1!D26 | F7: =Item1!E26 | G7: =Item1!F26 | H7: =Item1!G26 | I7: =Item1!H26 | ... O7: =Item1!N26
A8: Item1 | B8: =Item1!A27 | C8: =Item1!B27 | D8: =Item1!C27 | E8: =Item1!D27 | F8: =Item1!E27 | G8: =Item1!F27 | H8: =Item1!G27 | I8: =Item1!H27 | ... O8: =Item1!N27
A9: Item1 | B9: =Item1!A28 | C9: =Item1!B28 | D9: =Item1!C28 | E9: =Item1!D28 | F9: =Item1!E28 | G9: =Item1!F28 | H9: =Item1!G28 | I9: =Item1!H28 | ... O9: =Item1!N28
A10: Item1 | B10: =Item1!A29 | C10: =Item1!B29 | D10: =Item1!C29 | E10: =Item1!D29 | F10: =Item1!E29 | G10: =Item1!F29 | H10: =Item1!G29 | I10: =Item1!H29 | ... O10: =Item1!N29
A11: Item1 | B11: =Item1!A30 | C11: =Item1!B30 | D11: =Item1!C30 | E11: =Item1!D30 | F11: =Item1!E30 | G11: =Item1!F30 | H11: =Item1!G30 | I11: =Item1!H30 | ... O11: =Item1!N30
A12: Item1 | B12: =Item1!A31 | C12: =Item1!B31 | D12: =Item1!C31 | E12: =Item1!D31 | F12: =Item1!E31 | G12: =Item1!F31 | H12: =Item1!G31 | I12: =Item1!H31 | ... O12: =Item1!N31
A13: Item1 | B13: =Item1!A32 | C13: =Item1!B32 | D13: =Item1!C32 | E13: =Item1!D32 | F13: =Item1!E32 | G13: =Item1!F32 | H13: =Item1!G32 | I13: =Item1!H32 | ... O13: =Item1!N32
... A201: Item1 | B201: =Item1!A220 | C201: =Item1!B220 | D201: =Item1!C220 | E201: =Item1!D220 | F201: =Item1!E220 | G201: =Item1!F220 | H201: =Item1!G220 | I201: =Item1!H220 | ... O201: =Item1!N220
A202: Item2 | B202: =Item2!A23 | C202: =Item2!B23 | D202: =Item2!C23 | E202: =Item2!D23 | F202: =Item2!E23 | G202: =Item2!F23 | H202: =Item2!G23 | I202: =Item2!H23 | ... O202: =Item2!N23
A203: Item2 | B203: =Item2!A24 | C203: =Item2!B24 | D203: =Item2!C24 | E203: =Item2!D24 | F203: =Item2!E24 | G203: =Item2!F24 | H203: =Item2!G24 | I203: =Item2!H24 | ... O203: =Item2!N24
A204: Item2 | B204: =Item2!A25 | C204: =Item2!B25 | D204: =Item2!C25 | E204: =Item2!D25 | F204: =Item2!E25 | G204: =Item2!F25 | H204: =Item2!G25 | I204: =Item2!H25 | ... O204: =Item2!N25
A205: Item2 | B205: =Item2!A26 | C205: =Item2!B26 | D205: =Item2!C26 | E205: =Item2!D26 | F205: =Item2!E26 | G205: =Item2!F26 | H205: =Item2!G26 | I205: =Item2!H26 | ... O205: =Item2!N26
A206: Item2 | B206: =Item2!A27 | C206: =Item2!B27 | D206: =Item2!C27 | E206: =Item2!D27 | F206: =Item2!E27 | G206: =Item2!F27 | H206: =Item2!G27 | I206: =Item2!H27 | ... O206: =Item2!N27
A207: Item2 | B207: =Item2!A28 | C207: =Item2!B28 | D207: =Item2!C28 | E207: =Item2!D28 | F207: =Item2!E28 | G207: =Item2!F28 | H207: =Item2!G28 | I207: =Item2!H28 | ... O207: =Item2!N28
A208: Item2 | B208: =Item2!A29 | C208: =Item2!B29 | D208: =Item2!C29 | E208: =Item2!D29 | F208: =Item2!E29 | G208: =Item2!F29 | H208: =Item2!G29 | I208: =Item2!H29 | ... O208: =Item2!N29
A209: Item2 | B209: =Item2!A30 | C209: =Item2!B30 | D209: =Item2!C30 | E209: =Item2!D30 | F209: =Item2!E30 | G209: =Item2!F30 | H209: =Item2!G30 | I209: =Item2!H30 | ... O209: =Item2!N30
A210: Item2 | B210: =Item2!A31 | C210: =Item2!B31 | D210: =Item2!C31 | E210: =Item2!D31 | F210: =Item2!E31 | G210: =Item2!F31 | H210: =Item2!G31 | I210: =Item2!H31 | ... O210: =Item2!N31
A211: Item2 | B211: =Item2!A32 | C211: =Item2!B32 | D211: =Item2!C32 | E211: =Item2!D32 | F211: =Item2!E32 | G211: =Item2!F32 | H211: =Item2!G32 | I211: =Item2!H32 | ... O211: =Item2!N32
A212: Item2 | B212: =Item2!A33 | C212: =Item2!B33 | D212: =Item2!C33 | E212: =Item2!D33 | F212: =Item2!E33 | G212: =Item2!F33 | H212: =Item2!G33 | I212: =Item2!H33 | ... O212: =Item2!N33
A213: Item2 | B213: =Item2!A34 | C213: =Item2!B34 | D213: =Item2!C34 | E213: =Item2!D34 | F213: =Item2!E34 | G213: =Item2!F34 | H213: =Item2!G34 | I213: =Item2!H34 | ... O213: =Item2!N34
... A401: Item2 | B401: =Item2!A222 | C401: =Item2!B222 | D401: =Item2!C222 | E401: =Item2!D222 | F401: =Item2!E222 | G401: =Item2!F222 | H401: =Item2!G222 | I401: =Item2!H222 | ... O401: =Item2!N222
A402: Item3 | B402: =Item3!A22 | C402: =Item3!B22 | D402: =Item3!C22 | E402: =Item3!D22 | F402: =Item3!E22 | G402: =Item3!F22 | H402: =Item3!G22 | I402: =Item3!H22 | ... O402: =Item3!N22
A403: Item3 | B403: =Item3!A23 | C403: =Item3!B23 | D403: =Item3!C23 | E403: =Item3!D23 | F403: =Item3!E23 | G403: =Item3!F23 | H403: =Item3!G23 | I403: =Item3!H23 | ... O403: =Item3!N23
A404: Item3 | B404: =Item3!A24 | C404: =Item3!B24 | D404: =Item3!C24 | E404: =Item3!D24 | F404: =Item3!E24 | G404: =Item3!F24 | H404: =Item3!G24 | I404: =Item3!H24 | ... O404: =Item3!N24
A405: Item3 | B405: =Item3!A25 | C405: =Item3!B25 | D405: =Item3!C25 | E405: =Item3!D25 | F405: =Item3!E25 | G405: =Item3!F25 | H405: =Item3!G25 | I405: =Item3!H25 | ... O405: =Item3!N25
A406: Item3 | B406: =Item3!A26 | C406: =Item3!B26 | D406: =Item3!C26 | E406: =Item3!D26 | F406: =Item3!E26 | G406: =Item3!F26 | H406: =Item3!G26 | I406: =Item3!H26 | ... O406: =Item3!N26
A407: Item3 | B407: =Item3!A27 | C407: =Item3!B27 | D407: =Item3!C27 | E407: =Item3!D27 | F407: =Item3!E27 | G407: =Item3!F27 | H407: =Item3!G27 | I407: =Item3!H27 | ... O407: =Item3!N27
A408: Item3 | B408: =Item3!A28 | C408: =Item3!B28 | D408: =Item3!C28 | E408: =Item3!D28 | F408: =Item3!E28 | G408: =Item3!F28 | H408: =Item3!G28 | I408: =Item3!H28 | ... O408: =Item3!N28
A409: Item3 | B409: =Item3!A29 | C409: =Item3!B29 | D409: =Item3!C29 | E409: =Item3!D29 | F409: =Item3!E29 | G409: =Item3!F29 | H409: =Item3!G29 | I409: =Item3!H29 | ... O409: =Item3!N29
A410: Item3 | B410: =Item3!A30 | C410: =Item3!B30 | D410: =Item3!C30 | E410: =Item3!D30 | F410: =Item3!E30 | G410: =Item3!F30 | H410: =Item3!G30 | I410: =Item3!H30 | ... O410: =Item3!N30
A411: Item3 | B411: =Item3!A31 | C411: =Item3!B31 | D411: =Item3!C31 | E411: =Item3!D31 | F411: =Item3!E31 | G411: =Item3!F31 | H411: =Item3!G31 | I411: =Item3!H31 | ... O411: =Item3!N31
A412: Item3 | B412: =Item3!A32 | C412: =Item3!B32 | D412: =Item3!C32 | E412: =Item3!D32 | F412: =Item3!E32 | G412: =Item3!F32 | H412: =Item3!G32 | I412: =Item3!H32 | ... O412: =Item3!N32
A413: Item3 | B413: =Item3!A33 | C413: =Item3!B33 | D413: =Item3!C33 | E413: =Item3!D33 | F413: =Item3!E33 | G413: =Item3!F33 | H413: =Item3!G33 | I413: =Item3!H33 | ... O413: =Item3!N33
... A601: Item3 | B601: =Item3!A221 | C601: =Item3!B221 | D601: =Item3!C221 | E601: =Item3!D221 | F601: =Item3!E221 | G601: =Item3!F221 | H601: =Item3!G221 | I601: =Item3!H221 | ... O601: =Item3!N221
...
